# Converted from schematic
# THIS TEMPLATE USES DEFAULTS!  Please edit for corrections.
# If you need help, consult template_rules.txt

weight=1
embed_into_distance=0
acceptable_target_blocks=stone,grass,dirt,sand,gravel,110
dimensions=14,12,17
allowable_overhang=0
max_leveling=2
leveling_buffer=1
preserve_water=0
preserve_lava=0
preserve_plants=0


rule1=0,100,stonebrick
rule2=1,100,redstone_torch-5
rule3=0,100,stone
rule4=1,100,redstone_wire
rule5=0,100,oak_stairs-2
rule6=0,100,oak_stairs
rule7=0,100,oak_stairs-1
rule8=0,100,oak_stairs-3
rule9=2,100,ladder-5
rule10=2,100,ladder-4
rule11=2,100,tripwire_hook-4
rule12=2,100,tripwire-4
rule13=2,100,tripwire_hook-6
rule14=0,100,bookshelf
rule15=0,100,bookshelf
rule16=0,100,bookshelf
rule17=0,100,web
rule18=1,100,wooden_door-4
rule19=1,100,wooden_door-2
rule20=0,100,chest-4
rule21=0,100,ChestGenHook:pyramidJungleDispenser-11
rule22=2,100,torch-2
rule23=0,100,glass_pane
rule24=2,100,torch-3
rule25=2,100,torch-1
rule26=1,100,wooden_door-8
rule27=2,100,torch-4
rule28=0,100,planks
rule29=0,100,log
# Warding rune placeholder
rule30=0,100,MobSpawner:Skeleton,MobSpawner:Zombie,MobSpawner:Spider
rule31=0,100,chest-2
rule32=0,100,wooden_slab-8
rule33=0,100,wooden_slab


layer
0,0,8,6,5,0,0,0,0,0,0,0,0,0,0,0,0
1,1,3,3,3,1,1,0,0,0,0,0,0,0,0,0,0
1,3,3,3,3,3,1,1,1,1,0,0,0,0,0,0,0
3,3,3,3,3,3,3,1,1,1,0,1,1,1,1,0,0
3,3,3,3,3,3,3,3,3,1,1,3,3,3,1,1,0
1,3,3,3,3,3,3,3,3,3,3,3,3,3,2,1,0
1,3,3,3,3,3,3,3,3,3,3,3,3,3,2,1,0
3,3,3,3,3,3,3,3,0,1,1,3,3,3,1,1,0
3,3,3,3,3,3,3,4,0,1,0,1,1,1,1,0,0
1,3,3,3,3,3,1,1,1,1,0,0,0,0,0,0,0
1,1,3,3,3,1,1,0,0,0,0,0,0,0,0,0,0
0,0,8,7,5,0,0,0,0,0,0,0,0,0,0,0,0
endlayer

layer
0,0,0,0,0,0,0,0,0,0,0,0,0,0,0,0,0
1,3,3,18,3,3,1,0,0,0,0,0,0,0,0,0,0
3,0,0,0,0,0,3,1,1,1,0,0,0,0,0,0,0
3,0,0,0,0,0,3,3,3,1,0,3,3,3,0,0,0
3,0,0,0,0,0,14,11,3,3,3,0,9,0,3,0,0
3,0,0,0,0,0,15,12,0,0,0,0,0,0,1,3,0
3,0,0,0,0,0,16,12,0,0,0,0,0,0,1,3,0
3,0,0,0,0,0,14,13,3,3,3,0,10,0,3,0,0
3,0,0,0,0,0,3,3,3,1,0,3,3,3,0,0,0
3,20,0,0,0,17,3,1,1,1,0,0,0,0,0,0,0
1,3,3,19,3,3,1,0,0,0,0,0,0,0,0,0,0
0,0,0,0,0,0,0,0,0,0,0,0,0,0,0,0,0
endlayer

layer
0,0,0,0,0,0,0,0,0,0,0,0,0,0,0,0,0
3,23,3,26,3,23,3,0,0,0,0,0,0,0,0,0,0
3,0,25,0,25,0,3,0,0,0,0,0,0,0,0,0,0
3,27,0,0,0,24,3,3,3,0,0,3,3,3,0,0,0
23,0,0,0,0,0,14,0,3,3,3,0,9,0,3,0,0
23,0,0,0,0,0,15,0,0,0,0,0,0,0,21,3,0
23,0,0,0,0,0,16,0,0,0,0,0,0,0,21,3,0
23,0,0,0,0,0,14,22,3,3,3,0,10,0,3,0,0
3,27,0,0,0,24,3,3,3,0,0,3,3,3,0,0,0
3,0,22,0,22,0,3,0,0,0,0,0,0,0,0,0,0
3,23,3,26,3,23,3,0,0,0,0,0,0,0,0,0,0
0,0,0,0,0,0,0,0,0,0,0,0,0,0,0,0,0
endlayer

layer
0,0,0,0,0,0,0,0,0,0,0,0,0,0,0,0,0
1,23,3,3,3,23,3,0,0,0,0,0,0,0,0,0,0
3,17,0,0,0,17,3,0,0,0,0,0,0,0,0,0,0
3,0,0,0,0,0,3,3,3,0,0,3,3,3,0,0,0
23,0,0,0,0,0,14,0,3,3,3,0,9,0,3,0,0
23,0,0,0,0,0,15,0,0,0,0,0,0,0,0,3,0
23,0,0,0,0,0,16,0,0,0,0,0,0,0,0,3,0
23,0,0,0,0,0,14,0,3,3,3,0,10,0,3,0,0
3,0,0,0,0,0,3,3,3,0,0,3,3,3,0,0,0
3,0,0,0,0,0,3,0,0,0,0,0,0,0,0,0,0
1,23,3,3,3,23,3,0,0,0,0,0,0,0,0,0,0
0,0,0,0,0,0,0,0,0,0,0,0,0,0,0,0,0
endlayer

layer
0,0,0,0,0,0,0,0,0,0,0,0,0,0,0,0,0
1,1,3,3,3,1,1,0,0,0,0,0,0,0,0,0,0
1,3,3,3,3,3,1,0,0,0,0,0,0,0,0,0,0
3,3,3,3,3,3,3,3,1,0,0,3,3,3,0,0,0
3,3,3,3,3,3,3,3,3,3,3,0,9,0,3,0,0
3,3,3,3,3,3,3,3,3,3,0,0,0,0,0,3,0
3,3,3,3,3,3,3,3,3,3,0,0,0,0,0,3,0
3,3,3,3,3,3,3,3,3,3,3,0,10,0,3,0,0
3,3,3,3,3,3,3,3,1,0,0,3,3,3,0,0,0
1,3,3,3,3,3,1,0,0,0,0,0,0,0,0,0,0
1,1,3,3,3,1,1,0,0,0,0,0,0,0,0,0,0
0,0,0,0,0,0,0,0,0,0,0,0,0,0,0,0,0
endlayer

layer
0,0,0,0,0,0,0,0,0,0,0,0,0,0,0,0,0
0,0,0,0,0,0,0,0,0,0,0,0,0,0,0,0,0
0,0,0,0,0,0,0,0,0,0,0,0,0,0,0,0,0
0,0,0,0,0,0,0,0,0,0,0,3,3,3,0,0,0
0,0,0,0,0,0,0,0,0,0,3,25,9,25,3,0,0
0,0,0,0,0,0,0,0,0,3,0,0,0,0,0,3,0
0,0,0,0,0,0,0,0,0,3,0,0,0,0,0,3,0
0,0,0,0,0,0,0,0,0,0,3,22,10,22,3,0,0
0,0,0,0,0,0,0,0,0,0,0,3,3,3,0,0,0
0,0,0,0,0,0,0,0,0,0,0,0,0,0,0,0,0
0,0,0,0,0,0,0,0,0,0,0,0,0,0,0,0,0
0,0,0,0,0,0,0,0,0,0,0,0,0,0,0,0,0
endlayer

layer
0,0,0,0,0,0,0,0,0,0,0,0,0,0,0,0,0
0,0,0,0,0,0,0,0,0,0,0,0,0,0,0,0,0
0,0,0,0,0,0,0,0,0,0,0,0,0,0,0,0,0
0,0,0,0,0,0,0,0,0,0,0,1,1,1,0,0,0
0,0,0,0,0,0,0,0,0,0,1,0,9,0,1,0,0
0,0,0,0,0,0,0,0,0,1,0,0,0,0,0,1,0
0,0,0,0,0,0,0,0,0,1,0,0,0,0,0,1,0
0,0,0,0,0,0,0,0,0,0,1,0,10,0,1,0,0
0,0,0,0,0,0,0,0,0,0,0,1,1,1,0,0,0
0,0,0,0,0,0,0,0,0,0,0,0,0,0,0,0,0
0,0,0,0,0,0,0,0,0,0,0,0,0,0,0,0,0
0,0,0,0,0,0,0,0,0,0,0,0,0,0,0,0,0
endlayer

layer
0,0,0,0,0,0,0,0,0,0,0,0,0,0,0,0,0
0,0,0,0,0,0,0,0,0,0,0,0,0,0,0,0,0
0,0,0,0,0,0,0,0,0,0,0,0,0,0,0,0,0
0,0,0,0,0,0,0,0,0,0,0,3,3,3,0,0,0
0,0,0,0,0,0,0,0,0,0,3,0,9,0,3,0,0
0,0,0,0,0,0,0,0,0,3,0,0,0,0,0,3,0
0,0,0,0,0,0,0,0,0,3,0,0,0,0,0,3,0
0,0,0,0,0,0,0,0,0,0,3,0,10,0,3,0,0
0,0,0,0,0,0,0,0,0,0,0,3,3,3,0,0,0
0,0,0,0,0,0,0,0,0,0,0,0,0,0,0,0,0
0,0,0,0,0,0,0,0,0,0,0,0,0,0,0,0,0
0,0,0,0,0,0,0,0,0,0,0,0,0,0,0,0,0
endlayer

layer
0,0,0,0,0,0,0,0,0,0,0,0,0,0,0,0,0
0,0,0,0,0,0,0,0,0,0,0,0,0,0,0,0,0
0,0,0,0,0,0,0,0,0,0,0,0,0,0,0,0,0
0,0,0,0,0,0,0,0,0,0,0,3,3,3,0,0,0
0,0,0,0,0,0,0,0,0,0,3,0,9,0,3,0,0
0,0,0,0,0,0,0,0,0,3,0,0,0,0,0,3,0
0,0,0,0,0,0,0,0,0,3,0,0,0,0,0,3,0
0,0,0,0,0,0,0,0,0,0,3,0,10,0,3,0,0
0,0,0,0,0,0,0,0,0,0,0,3,3,3,0,0,0
0,0,0,0,0,0,0,0,0,0,0,0,0,0,0,0,0
0,0,0,0,0,0,0,0,0,0,0,0,0,0,0,0,0
0,0,0,0,0,0,0,0,0,0,0,0,0,0,0,0,0
endlayer

layer
0,0,0,0,0,0,0,0,0,0,0,0,0,0,0,0,0
0,0,0,0,0,0,0,0,0,0,0,0,0,0,0,0,0
0,0,0,0,0,0,0,0,0,0,0,0,0,0,0,0,0
0,0,0,0,0,0,0,0,0,0,0,3,3,3,0,0,0
0,0,0,0,0,0,0,0,0,0,3,3,9,3,3,0,0
0,0,0,0,0,0,0,0,0,3,3,3,3,3,3,3,0
0,0,0,0,0,0,0,0,0,3,3,3,3,3,3,3,0
0,0,0,0,0,0,0,0,0,0,3,3,10,3,3,0,0
0,0,0,0,0,0,0,0,0,0,0,3,3,3,0,0,0
0,0,0,0,0,0,0,0,0,0,0,0,0,0,0,0,0
0,0,0,0,0,0,0,0,0,0,0,0,0,0,0,0,0
0,0,0,0,0,0,0,0,0,0,0,0,0,0,0,0,0
endlayer

layer
0,0,0,0,0,0,0,0,0,0,0,0,0,0,0,0,0
0,0,0,0,0,0,0,0,0,0,0,0,0,0,0,0,0
0,0,0,0,0,0,0,0,0,0,0,0,0,0,0,0,0
0,0,0,0,0,0,0,0,0,0,0,28,28,28,0,0,0
0,0,0,0,0,0,0,0,0,0,29,0,9,0,29,0,0
0,0,0,0,0,0,0,0,0,28,31,0,0,0,30,28,0
0,0,0,0,0,0,0,0,0,28,31,0,0,0,0,28,0
0,0,0,0,0,0,0,0,0,0,29,0,10,0,29,0,0
0,0,0,0,0,0,0,0,0,0,0,28,28,28,0,0,0
0,0,0,0,0,0,0,0,0,0,0,0,0,0,0,0,0
0,0,0,0,0,0,0,0,0,0,0,0,0,0,0,0,0
0,0,0,0,0,0,0,0,0,0,0,0,0,0,0,0,0
endlayer

layer
0,0,0,0,0,0,0,0,0,0,0,0,0,0,0,0,0
0,0,0,0,0,0,0,0,0,0,0,0,0,0,0,0,0
0,0,0,0,0,0,0,0,0,0,0,0,0,0,0,0,0
0,0,0,0,0,0,0,0,0,0,0,28,23,28,0,0,0
0,0,0,0,0,0,0,0,0,0,29,0,0,0,29,0,0
0,0,0,0,0,0,0,0,0,28,0,0,0,0,0,28,0
0,0,0,0,0,0,0,0,0,28,0,0,0,0,0,28,0
0,0,0,0,0,0,0,0,0,0,29,0,0,0,29,0,0
0,0,0,0,0,0,0,0,0,0,0,28,23,28,0,0,0
0,0,0,0,0,0,0,0,0,0,0,0,0,0,0,0,0
0,0,0,0,0,0,0,0,0,0,0,0,0,0,0,0,0
0,0,0,0,0,0,0,0,0,0,0,0,0,0,0,0,0
endlayer

layer
0,0,0,0,0,0,0,0,0,0,0,0,0,0,0,0,0
0,0,0,0,0,0,0,0,0,0,0,0,0,0,0,0,0
0,0,0,0,0,0,0,0,0,0,0,32,32,32,0,0,0
0,0,0,0,0,0,0,0,0,0,32,28,28,28,32,0,0
0,0,0,0,0,0,0,0,0,32,29,0,0,0,29,32,0
0,0,0,0,0,0,0,0,32,28,0,0,0,0,0,28,32
0,0,0,0,0,0,0,0,32,28,0,0,0,0,0,28,32
0,0,0,0,0,0,0,0,0,32,29,0,0,0,29,32,0
0,0,0,0,0,0,0,0,0,0,32,28,28,28,32,0,0
0,0,0,0,0,0,0,0,0,0,0,32,32,32,0,0,0
0,0,0,0,0,0,0,0,0,0,0,0,0,0,0,0,0
0,0,0,0,0,0,0,0,0,0,0,0,0,0,0,0,0
endlayer

layer
0,0,0,0,0,0,0,0,0,0,0,0,0,0,0,0,0
0,0,0,0,0,0,0,0,0,0,0,0,0,0,0,0,0
0,0,0,0,0,0,0,0,0,0,0,0,0,0,0,0,0
0,0,0,0,0,0,0,0,0,0,0,0,0,0,0,0,0
0,0,0,0,0,0,0,0,0,0,33,33,33,33,33,0,0
0,0,0,0,0,0,0,0,0,0,33,32,32,32,33,0,0
0,0,0,0,0,0,0,0,0,0,33,32,32,32,33,0,0
0,0,0,0,0,0,0,0,0,0,33,33,33,33,0,0,0
0,0,0,0,0,0,0,0,0,0,0,0,0,0,0,0,0
0,0,0,0,0,0,0,0,0,0,0,0,0,0,0,0,0
0,0,0,0,0,0,0,0,0,0,0,0,0,0,0,0,0
0,0,0,0,0,0,0,0,0,0,0,0,0,0,0,0,0
endlayer

